<?xml version='1.0'?>
<sdf version='1.4'>
<model name="mobile">
	<static>false</static>
	<link name='body'>
		<pose>0 0 0.05 0 0 0</pose>
		<collision name='collision'>
			<geometry>
				<mesh><uri>file://top.dae</uri></mesh>
			</geometry>
		</collision>

		<visual name='visual'>
			<geometry>
				<mesh><uri>file://top.dae</uri></mesh>
			</geometry>
		</visual>
	</link>
	
	<link name='left_leg_b'>
		<pose>-0.03 -0.04 0.04 1.570796 3.14159 0</pose>
		<collision name='left_leg_b_collision'>
			<geometry>
				<mesh><uri>file://leftleg.dae</uri></mesh>
			</geometry>
		</collision>

		<visual name='left_leg_b_visual'>
			<geometry>
				<mesh><uri>file://leftleg.dae</uri></mesh>
			</geometry>
		</visual>
	</link>

	<link name='right_leg_b'>
		<pose>0.037 -0.04 0.04 0 3.14159 0</pose>
		<collision name='right_leg_b_collision'>
			<geometry>
				<mesh><uri>file://leftleg.dae</uri></mesh>
			</geometry>
		</collision>

		<visual name='right_leg_b_visual'>
			<geometry>
				<mesh><uri>file://leftleg.dae</uri></mesh>
			</geometry>
		</visual>
	</link>

	<link name='left_leg_m'>
		<pose>-0.03 0.031 0.04 0 3.14159 0</pose>
		<collision name='left_leg_m_collision'>
			<geometry>
				<mesh><uri>file://leftleg.dae</uri></mesh>
			</geometry>
		</collision>

		<visual name='left_leg_m_visual'>
			<geometry>
				<mesh><uri>file://leftleg.dae</uri></mesh>
			</geometry>
		</visual>
	</link>

	<link name='right_leg_m'>
		<pose>0.037 0.031 0.04 1.570796 3.14159 0</pose>
		<collision name='right_leg_b_collision'>
			<geometry>
				<mesh><uri>file://leftleg.dae</uri></mesh>
			</geometry>
		</collision>

		<visual name='right_leg_m_visual'>
			<geometry>
				<mesh><uri>file://leftleg.dae</uri></mesh>
			</geometry>
		</visual>
	</link>


	<link name='left_leg_f'>
		<pose>-0.03 0.101 0.04 1.570796 3.14159 0</pose>
		<collision name='left_leg_f_collision'>
			<geometry>
				<mesh><uri>file://leftleg.dae</uri></mesh>
			</geometry>
		</collision>

		<visual name='left_leg_f_visual'>
			<geometry>
				<mesh><uri>file://leftleg.dae</uri></mesh>
			</geometry>
		</visual>
	</link>

	<link name='right_leg_f'>
		<pose>0.037 0.101 0.04 0 3.14159 0</pose>
		<collision name='right_leg_f_collision'>
			<geometry>
				<mesh><uri>file://leftleg.dae</uri></mesh>
			</geometry>
		</collision>

		<visual name='right_leg_f_visual'>
			<geometry>
				<mesh><uri>file://leftleg.dae</uri></mesh>
			</geometry>
		</visual>
	</link>
	<joint type="revolute" name="left_b">
		<pose>0 0 0 0 0 0</pose>
		<child>left_leg_b</child>
		<parent>body</parent>
		<axis><xyz>1 0 0</xyz></axis>
	</joint>

	<joint type="revolute" name="left_m">
		<pose>0 0 0 0 0 0</pose>
		<child>left_leg_m</child>
		<parent>body</parent>
		<axis><xyz>1 0 0</xyz></axis>
	</joint>

	<joint type="revolute" name="left_f">
		<pose>0 0 0 0 0 0</pose>
		<child>left_leg_f</child>
		<parent>body</parent>
		<axis><xyz>1 0 0</xyz></axis>
	</joint>

	<joint type="revolute" name="right_b">
		<pose>0 0 0 0 0 0</pose>
		<child>right_leg_b</child>
		<parent>body</parent>
		<axis><xyz>1 0 0</xyz></axis>
	</joint>

	<joint type="revolute" name="right_m">
		<pose>0 0 0 0 0 0</pose>
		<child>right_leg_m</child>
		<parent>body</parent>
		<axis><xyz>1 0 0</xyz></axis>
	</joint>

	<joint type="revolute" name="right_f">
		<pose>0 0 0 0 0 0</pose>
		<child>right_leg_f</child>
		<parent>body</parent>
		<axis><xyz>1 0 0</xyz></axis>
	</joint>
</model>
</sdf>
